Workbook

Sheet Product
A1: Company/Brand | B1: Product Render/Image | C1: Product Name | D1: Item # | E1: Product Priority | F1: Launch date | G1: UPC # | H1: UPC Image | I1: Canadian Compliant?

Sheet BOX ONLY
A1: Item | B1: Owner | C1: Copy | D1: Notes
A2: BOX ONLY
A3: Product Name | B3: Product Marketing
A4: SKU | B4: Product Marketing
A5: Collection Name
A6: Product Description
A7: Main Statement (Tagline) | B7: Product Marketing
A8: Features (6 Max) | B8: Product Marketing
A9: 1 | B9: Copy Writer
A10: 2
A11: 3 | B11: Copy Writer
A12: 4 | B12: Copy Writer
A13: 5 | B13: Copy Writer
A14: 6 | B14: Copy Writer
A15: Icons (6 Max) | B15: Copy Writer
A16: 1 | B16: Copy Writer
A17: 2
A18: 3 | B18: Copy Writer
A19: 4 | B19: Copy Writer
A20: 5 | B20: Copy Writer
A21: 6 | B21: Copy Writer
A22: Three Call Outs (on front of box - 35 character max) | B22: Copy Writer
A23: 1 | B23: Copy Writer
A24: 2 | B24: Product Marketing
A25: 3 | B25: Product Marketing
B26: Product Marketing | C26: ='Product Knowledge'!C24
A27: Infographic Details | B27: Product Marketing
B28: Product Marketing
A36: Consumer Facing Feature Bullets - LONG CAPITALIZED & BOLDED HIGHLIGHTED FEATURE leads into 1-2 sentences about
A45: Includes
A46: Made In | C46: Made in China Hecho en China Fabriqué en Chine SC Tools: Distributed by: StyleCraft, LLC. Boca Raton, FL 33487 ©2027 Gamma+ NA, LLC G+ Tools: Distributed by: Gamma+ NA, LLC. Boca Raton, FL 33487 ©2027 Gamma+ NA, LLC
A47: UPC
A48: Warranty | B48: 2 year
A49: Charger Voltage
A50: Social Handles
A51: Copyright Year
A52: Distributed By:
A53: Certifications

Sheet Product Testing

Sheet Product Knowledge
A1: Item | B1: Owner | C1: Answer | D1: Notes
A2: Core Consumer | B2: Product Marketing
A3: Why are we creating this item? (consumer need, competitive product, etc) | B3: Product Marketing
A4: What is the positioning statement? (story) | B4: Product Marketing
A5: Product Name Origin | B5: Product Marketing
A6: How does this product name tie to the story? | B6: Product Marketing
A7: Collection | B7: Product Marketing
A8: New Technology? | B8: Product Marketing
A9: Approved Pricing | B9: Product Marketing
A10: Good Better Best -Lineup | B10: Product Marketing
A11: Good Better Best -Performance | B11: Product Marketing
A12: Hair Type | B12: Product Marketing | D12: Select 1
A13: Features (full list) | B13: Product Marketing
B14: Product Marketing
B15: Product Marketing
B16: Product Marketing
B17: Product Marketing
B18: Product Marketing
B19: Product Marketing
B20: Product Marketing
B21: Product Marketing
B22: Product Marketing
A23: Up-sell (Sales play opportunity) | B23: Product Marketing
A24: Cross Sell Products | B24: Product Marketing
A25: Reason to Buy (Unique Selling Points) | B25: Product Marketing
A26: Expert Tip | B26: Product Marketing
A27: Comparison Chart WEB ONLY (Select two products to feature as comparisons on the DTC site and provide the SKUs. You may include products from either StyleCraft or Gamma+) | B27: Product Marketing | C27: Comp Item #1. Comp Item #2. | D27: Example: Main Product (SC601M) Rebel 2.0 vs Comp #1 - (GP601M) Boosted UP Comp #2 - (SC620W) Reign Clipper
A28: COMPS
A29: Comps for Buying Guide | B29: Product Marketing
A30: Trademark Symbol | B30: Product Marketing
A31: Warranty | B31: Product Marketing
A32: Certification Needed | B32: Product Marketing
A33: Rating Label | B33: Product Marketing
A34: Dieline | B34: Product Marketing | C34: Place Link
A35: Box Type | B35: Product Marketing
A36: Product LxWxH (in.) | B36: Product Marketing
A37: Product Weight (lbs.) | B37: Product Marketing
A38: Box LxWxH (in.) | B38: Product Marketing
A39: Measurement By | B39: Product Marketing
A40: Box Weight (lbs.) | B40: Product Marketing
...

Sheet Marketing Direction
A1: Item | B1: Owner | C1: Answer | D1: Notes
A2: Previous Product Reference | B2: Marketing
A3: Primary Goal (ex: Drive trial, awareness, revenue, retailer sell-in) | B3: Marketing
A4: Success KPIs (ex: revenue, ROAS, traffic, engagement, new users) | B4: Marketing
A5: Marketing Launch Timing (when should marketing kick off?) | B5: Marketing
A6: Core Audience (desctiption of who we think this product should be advertised to - more than Pro or Retail) | B6: Marketing
A7: Secondary Audience (if applicable) | B7: Marketing
A8: Consumer Barrier (what do we need our marketing to solve for or what question do we need to answer?) | B8: Marketing
A9: Messaging Direction (tone, messaging ideas or inspo) | B9: Marketing
A10: Product Name Origin | B10: Marketing
A11: Visual direction (in-salon, lifestyle, product-focused, etc.) | B11: Marketing
A12: Content ideas or territories (just direction not mandatory) | B12: Marketing
A13: Languages | B13: Marketing
A14: Do’s / Don’ts | B14: Marketing
A15: CHANNEL STRATEGY/CONTENT DELIVERABLES
A16: Web Coverage | B16: Marketing
A17: Where should we be advertising? (based on priority and budget) | B17: Marketing
A18: Print Material? | B18: Marketing
A19: Trade Show Launch | B19: Marketing | D19: (add details here)
A20: Educator Sampling | B20: Marketing | D20: (add details here)
A21: Influencer Sampling | B21: Marketing | D21: (add details here)
A22: Stylecraft Sales Team | B22: Marketing | D22: (add details here)
A23: External Sales Rep Sampling | B23: Marketing | D23: (add details here)
A24: Key Accounts Sampling | B24: Marketing | D24: (add details here)
A25: Promo | B25: Marketing | D25: (add details here)

Sheet Product FAQ
A1: Question / Answer
A2: Product Marketing | B2: Copy Writer
A3: FAQ's
A4: Q:
A5: A:
A7: Q:
A8: A:
A10: Q:
A11: A:
A13: Our Differrentiators
A15: Dealer Gross Margins: %
A16: Retail Gross Margin: %
A17: Intial Quantities ordered: #
A18: Selling Position
... A23: 3:

Sheet Final Copy
A1: Item | B1: Owner | C1: Copy | D1: Notes
A2: Positioning Statement | B2: Copy Writer
A3: Tone (ex: confident, playful, witty) | B3: Copy Writer
A4: Core Message (What is the ONE thing we want the consumer to remember?) | B4: Copy Writer
A5: Tagline/Headline - Sexy | B5: Copy Writer
A6: Tagline/Headline - Techie (these are to reflect the three callouts on front)
A7: Secondary Messaging | B7: Copy Writer
A8: Description (romance copy) 2,000 Character Limit 2 paragraphs with feature bulllets | B8: Copy Writer
A9: Consumer Facing Feature Bullets - LONG CAPITALIZED & BOLDED HIGHLIGHTED FEATURE leads into 1-2 sentences about
B15: Copy Writer
A16: Consumer Facing Feature Bullets - CONDENSED Highlighted Feature + 1-4 words describing it, no colons or periods (optional) | B16: Copy Writer
B17: Copy Writer
B18: Copy Writer
B19: Copy Writer
B20: Copy Writer
A22: Consumer Facing Feature Bullets - TOP 3 (3 Main Points in order, unless special feature)
B23: Copy Writer
B24: Copy Writer
A25: How to Use Messaging | B25: Copy Writer
A26: How to Take Care Romance Copy | B26: Copy Writer
A27: Content Hook (social) | B27: Copy Writer
A28: Social Caption Example | B28: Copy Writer
A29: Keyword Search Terms - no repeat words, comp brands | B29: Copy Writer
A30: Messaging risks (no-no's) | B30: Copy Writer
A31: Icons Use the ones on the final Box. | B31: Copy Writer
A32: Other Messaging
A33: E-COMMERCE ONLY
A34: Amazon Long Title – Don’t use “size” if SKU has variants (E-COMMERCE ONLY) | B34: Copy Writer
A35: E-commerce Title (E-commerce Only) | B35: Copy Writer
A36: Website Title – Don’t use “size” if SKU has variants (E-COMMERCE ONLY) | B36: Copy Writer
A37: Product feature - 3 key feature Tags (All Caps, 40-44 Chacter Limit) 1. Hero Technology 2. Performance 3. Lifestyle/Benefit | B37: Copy Writer | D37: (Charcter limit should include spaces and bullets) Format example: HIGH TORQUE • CRUNCHY CUTS • PRO FADES QUIET POWER • ZERO PULLING • CLEAN FADES IN2 VECTOR MOTOR • BULK REMOVAL • QUIET CUTS
A38: Tagline (Main) | B38: Copy Writer
A39: Product Despription - 1–2 sentence marketing summary | B39: Copy Writer | D39: Big Fluff
A40: Short Description (229 characters or less, including spaces) | B40: Copy Writer
A41: Suggested Use (200 characters or less, including spaces) | B41: Copy Writer
A42: Feature Bullets Top 3 For Web (Short Version - 100 character limit)
A43: 1 | B43: Copy Writer | D43: Feature Title + marketing description or benefit
A44: 2 | B44: Copy Writer | D44: Feature Title + marketing description or benefit
A45: 3 | B45: Copy Writer | D45: Feature Title + marketing description or benefit
A46: Feature Bullets Top 3 for Hot Spot content for PDP Image (Long Version)
...

Sheet Austin Review
A1: Item | B1: Owner | C1: Copy | D1: Austin Notes
A2: Description (romance copy) 2,000 Character Limit - 2 paragraphs with bullets | B2: Copy Writer
A3: ='Final Copy'!A9 -> Consumer Facing Feature Bullets - LONG CAPITALIZED & BOLDED HIGHLIGHTED FEATURE leads into 1-2 sentences about | B3: ='Final Copy'!B9
A4: ='Marketing Direction'!A3 -> Primary Goal (ex: Drive trial, awareness, revenue, retailer sell-in) | B4: ='Marketing Direction'!B3 -> Marketing
A5: ='Marketing Direction'!A6 -> Core Audience (desctiption of who we think this product should be advertised to - more than Pro or Retail) | B5: ='Marketing Direction'!B6 -> Marketing
A6: Consumer Facing Feature Bullets - TOP 3 (3 Main Points in order, unless special feature) | B6: Copy Writer
A7: Tagline/Headline - Sexy | B7: Copy Writer
A8: Core Message (What is the ONE thing we want the consumer to remember?) | B8: Copy Writer
A9: Social Caption Example | B9: Copy Writer
A10: Content Hook (social) | B10: Copy Writer

Sheet Product Purchasing
A1: Owner | B1: Item # | C1: Order Date | D1: Order Quantity | E1: AW Delivery | F1: Production Started | G1: Ship Date | H1: In Warehouse | I1: Sampling Launch | J1: Pre-Order | K1: In-Market
A2: Project Manager

Sheet Creative Playbook
A1: Item | B1: Owner | C1: Link | D1: Notes
A2: Creative Playbook (what does this look like, feel like, and how do we execute it consistently across channels?) | B2: Creative Services | D2: What to include (doesn't have to be all): Campaign idea or platform Core visual or storytelling hook Lighting style (bright, moody, natural, studio) Environment (salon, home, editorial, clean backdrop) Framing (close-up, handheld, polished, UGC feel) Color palette (if relevant) Product prominence rules What should never happen? (Visual no-go’s)
A4: Sales Slides | B4: LINK
A6: Dropbox Assets | B6: LINK

Sheet GTM Plan DeliverablesAsana Proj
A1: Asana Project | B1: Project Manager | C1: {PM to insert link to project once in Asana}
A2: Channel | B2: Lead | C2: Content Needs | D2: Launch Date (first date) | E2: Notes
A3: DIGITAL
A4: PDP Page | B4: Ecomm
A5: DTC/Brand.com | B5: Ecomm
A6: Amazon Store | B6: Ecomm
A7: Walmart Brand Store | B7: Ecomm
A8: Other Retail | B8: Ecomm
A9: Email | B9: Marketing Operations
A10: Organic Social (Meta) | B10: Social
A11: Organic Social (TT) | B11: Social
A12: Paid Social (Meta) | B12: Digital Marketing
A13: Paid Social (TT) | B13: Digital Marketing
A14: Paid Search | B14: Digital Marketing
A15: Amazon Ads | B15: Digital Marketing
... A17: Youtube | B17: Social
A19: PRINT
A20: Influencer Box | B20: Social
A21: Flyers/Cards | B21: Sales, Social
A22: POS | B22: Sales
A28: SALES
A29: Decks
A39: TRADE SHOW
A40: Booth Signage
A41: Product Sheet
A42: Education Classes
A43: Flyers
A44: Coupon/QR
A45: Decks
A48: PHOTOGRAPHY/VIDEO
A49: Video
A50: Pro-Photography
... A56: EXPERIENTIAL

Sheet Sampling Program
